<?xml version='1.0'?>

<robot name="myrobot" xmlns:xacro="http://www.ros.org/wiki/xacro">

<link name="robot_footprint"></link>
<xacro:include filename="$(find myrobot)/urdf/myrobot.gazebo" />

  <joint name="robot_footprint_joint" type="fixed">
    <origin xyz="0 0 0.1" rpy="0 0 0" />
    <parent link="robot_footprint"/>
    <child link="chassis" />
  </joint>

  <link name='chassis'>
    <pose>0 0 0.1 0 0 0</pose>

    <inertial>
      <mass value="15.0"/>
      <origin xyz="0.0 0 0" rpy=" 0 0 0"/>
      <inertia
          ixx="0.1" ixy="0" ixz="0"
          iyy="0.1" iyz="0"
          izz="0.1"
      />
    </inertial>

    <collision name='collision'>
      <origin xyz="0 0 0" rpy=" 0 0 0"/>
      <geometry>
        <box size=".4 .2 .1"/>
      </geometry>
    </collision>

    <visual name='chassis_visual'>
      <origin xyz="0 0 0" rpy=" 0 0 0"/>
      <geometry>
        <box size=".4 .2 .1"/>
      </geometry>
    </visual>

    <collision name='back_caster_collision'>
      <origin xyz="-0.15 0 -0.05" rpy=" 0 0 0"/>
      <geometry>
        <sphere radius="0.0499"/>
      </geometry>
    </collision>

    <visual name='back_caster_visual'>
      <origin xyz="-0.15 0 -0.05" rpy=" 0 0 0"/>
      <geometry>
        <sphere radius="0.05"/>
      </geometry>
    </visual>

    <collision name='front_caster_collision'>
      <origin xyz="0.15 0 -0.05" rpy=" 0 0 0"/>
      <geometry>
        <sphere radius="0.0499"/>
      </geometry>
    </collision>

    <visual name='front_caster_visual'>
      <origin xyz="0.15 0 -0.05" rpy=" 0 0 0"/>
      <geometry>
        <sphere radius="0.05"/>
      </geometry>
    </visual>

  </link>


<link name="link_right_wheel">
    <inertial>
      <mass value="5"/>
      <origin rpy="0 1.5707 1.5707" xyz="0 0 0"/>
      <inertia     ixx="0.1" ixy="0" ixz="0"
    iyy="0.1" iyz="0"
    izz="0.1"/>
    </inertial>

    <collision name="link_right_wheel_collision">
      <origin rpy="0 1.5707 1.5707" xyz="0 0 0" />
      <geometry>
        <cylinder length="0.05" radius="0.1"/>
      </geometry>
    </collision>

    <visual name="link_right_wheel_visual">
      <origin rpy="0 1.5707 1.5707" xyz="0 0 0" />
      <geometry>
        <cylinder length="0.05" radius="0.1"/>
      </geometry>
    </visual>
 </link>

  <joint type="continuous" name="right_wheel_hinge">
    <origin xyz="0 -0.15 0" rpy="0 0 0"/>
    <child link="link_right_wheel"/>
    <parent link="chassis"/>
    <axis xyz="0 1 0" rpy="0 0 0"/>
    <limit effort="10000" velocity="1000"/>
    <dynamics damping="1.0" friction="1.0"/>
  </joint>


<link name="link_left_wheel">
    <inertial>
      <mass value="5"/>
      <origin rpy="0 1.5707 1.5707" xyz="0.0 0 0"/>
      <inertia     ixx="0.1" ixy="0" ixz="0"
    iyy="0.1" iyz="0"
    izz="0.1"/>
    </inertial>

    <collision name="link_left_wheel_collision">
      <origin rpy="0 1.5707 1.5707" xyz="0 0 0" />
      <geometry>
        <cylinder length="0.05" radius="0.1"/>
      </geometry>
    </collision>

    <visual name="link_left_wheel_visual">
      <origin rpy="0 1.5707 1.5707" xyz="0 0 0" />
      <geometry>
        <cylinder length="0.05" radius="0.1"/>
      </geometry>
    </visual>
 </link>

  <joint type="continuous" name="left_wheel_hinge">
    <origin xyz="0 0.15 0" rpy="0 0 0"/>
    <child link="link_left_wheel"/>
    <parent link="chassis"/>
    <axis xyz="0 1 0" rpy="0 0 0"/>
    <limit effort="10000" velocity="1000"/>
    <dynamics damping="1.0" friction="1.0"/>
  </joint>

<link name="camera">
    <inertial>
      <mass value="0.1"/>
      <origin rpy="0 0 0" xyz="0 0 0"/>
      <inertia ixx="1e-6" ixy="0" ixz="0" iyy="1e-6" iyz="0" izz="1e-6"/>
    </inertial>
      <box_inertia m="0.1" x="0.05" y="0.05" z="0.05"/>

    <collision name="camera_collision">
      <origin xyz="0 0 0" rpy=" 0 0 0"/>
      <geometry>
        <box size=".05 .05 .05"/>
      </geometry>
    </collision>

    <visual name="camera_visual">
      <origin xyz="0 0 0" rpy=" 0 0 0"/>
      <geometry>
        <box size=".05 .05 .05"/>
      </geometry>
    </visual>
 </link>

  <joint type="fixed" name="camera_joint">
    <origin xyz="0.2 0 0" rpy="0 0 0"/>
    <child link="camera"/>
    <parent link="chassis"/>
    <axis xyz="0 1 0" rpy="0 0 0"/>
  </joint>

  <joint name="camera_link_optical" type="fixed">
    <origin xyz="0 0 0" rpy="0 0 0"/>
    <parent link="camera"/>
    <child link="camera_link_optical"/>
  </joint>

  <link name="camera_link_optical">
  </link>


<link name="hokuyo">
    <inertial>
      <mass value="1e-5"/>
      <origin rpy="0 0 0" xyz="0 0 0"/>
      <inertia ixx="1e-6" ixy="0" ixz="0" iyy="1e-6" iyz="0" izz="1e-6"/>
    </inertial>
      <box_inertia m="0.1" x="0.05" y="0.05" z="0.05"/>

    <visual name="hokuyo_visual">
      <origin xyz="0 0 0" rpy=" 0 0 0"/>
      <geometry>
        <mesh filename="package://myrobot/meshes/hokuyo.dae"/>
      </geometry>
    </visual>
 </link>

  <joint type="fixed" name="hokuyo_joint">
    <origin xyz="0.15 0 0.08" rpy="0 0 0"/>
    <child link="hokuyo"/>
    <parent link="chassis"/>
    <axis xyz="0 1 0" rpy="0 0 0"/>
  </joint>


  <material name="black">
    <color rgba="0.0 0.0 0.0 1.0"/>
  </material>
  <material name="blue">
    <color rgba="0.203125 0.23828125 0.28515625 1.0"/>
  </material>
  <material name="green">
    <color rgba="0.0 0.8 0.0 1.0"/>
  </material>
  <material name="grey">
    <color rgba="0.2 0.2 0.2 1.0"/>
  </material>
  <material name="orange">
    <color rgba="1.0 0.423529411765 0.0392156862745 1.0"/>
  </material>
  <material name="brown">
    <color rgba="0.870588235294 0.811764705882 0.764705882353 1.0"/>
  </material>
  <material name="red">
    <color rgba="0.80078125 0.12890625 0.1328125 1.0"/>
  </material>
  <material name="white">
    <color rgba="1.0 1.0 1.0 1.0"/>
  </material>  
  
  <gazebo reference="chassis">
    <material>Gazebo/Orange</material>
  </gazebo>
  <gazebo reference="link_left_wheel">
    <material>Gazebo/Blue</material>
  </gazebo>
  <gazebo reference="link_right_wheel">
    <material>Gazebo/Blue</material>
  </gazebo>
  <gazebo reference="camera">
    <material>Gazebo/Red</material>
  </gazebo>

</robot>

